Workbook

Sheet a、b、c、d、g
A1: 1 | B1: 配置选择 | C1: 板材 | E1: 门板材质 | F1: 门板工艺 | G1: 五金 | I1: 照明
C2: 奥地利 爱格 | E2: 柜体相同 | F2: 无 | G2: 中国品牌 | I2: 无
A3: 编号 | B3: a-100-230 | D3: 结构 | E3: {=INDEX(_xlfn.TEXTSPLIT(B3,"-"),1)} -> a | F3: 宽度 | G3: 100 | H3: 高度 | I3: {=INDEX(_xlfn.TEXTSPLIT(B3,"-"),3)} -> 230
A4: 分类 | B4: 部件 | C4: 规格（cm） | F4: 数量 | G4: 面积 m² | H4: 单价 （元） | I4: 小计 （元）
C5: 长 | D5: 宽 | E5: 厚
A6: 板材 | B6: 左侧板 | C6: =$I$3-6 -> 224 | D6: =60-2 -> 58 | E6: 1.8 | F6: 1 | G6: =C6*D6/10000*F6 -> 1.2992 | H6: =VLOOKUP($C$2,数据库!$B$1:$C$5,2,0) -> 195 | I6: =F6*G6*H6 -> 253.344
B7: 右侧板 | C7: =$I$3-6 -> 224 | D7: =60-2 -> 58 | E7: 1.8 | F7: 1 | G7: =C7*D7/10000*F7 -> 1.2992 | H7: =VLOOKUP($C$2,数据库!$B$1:$C$5,2,0) -> 195 | I7: =F7*G7*H7 -> 253.344
B8: 顶板 | C8: =$G$3-(1.8*2) -> 96.4 | D8: =60-2 -> 58 | E8: 1.8 | F8: 1 | G8: =C8*D8/10000*F8 -> 0.55912 | H8: =VLOOKUP($C$2,数据库!$B$1:$C$5,2,0) -> 195 | I8: =F8*G8*H8 -> 109.0284
B9: 底板 | C9: =$G$3-(1.8*2) -> 96.4 | D9: =60-2 -> 58 | E9: 1.8 | F9: 1 | G9: =C9*D9/10000*F9 -> 0.55912 | H9: =VLOOKUP($C$2,数据库!$B$1:$C$5,2,0) -> 195 | I9: =F9*G9*H9 -> 109.0284
B10: 厚背板 | C10: =$I$3-1.8-1.8-6 -> 220.4 | D10: =$G$3-(1.8*2) -> 96.4 | E10: 1.8 | F10: 1 | G10: =C10*D10/10000*F10 -> 2.124656 | H10: =VLOOKUP($C$2,数据库!$B$1:$C$5,2,0) -> 195 | I10: =F10*G10*H10 -> 414.30792
B11: 层板 | C11: =$G$3-(1.8*2) -> 96.4 | D11: =60-2-1.8 -> 56.2 | E11: 1.8 | F11: =VLOOKUP(E3,数据库!$A$21:$B$25,2,0)+(IF(AND(E3="g",I3>=51),1,0)) -> 2 | G11: =C11*D11/10000*F11 -> 1.083536 | H11: =VLOOKUP($C$2,数据库!$B$1:$C$5,2,0) -> 195 | I11: =F11*G11*H11 -> 422.57904
B12: 门板 | C12: =$I$3-6-0.44 -> 223.56 | D12: =$G$3-0.6 -> 99.4 | E12: 1.8 | F12: 1 | G12: =C12*D12/10000 -> 2.2221864 | H12: =VLOOKUP($C$2,数据库!$B$1:$C$5,2,0)+VLOOKUP($E$2,数据库!B7:C13,2,0)+VLOOKUP($F$2,数据库!B15:C18,2,0) -> 195 | I12: =F12*G12*H12 -> 433.32635
B13: 检修口 | C13: 19.8 | D13: =G3-1.8-1.8-0.4 -> 96 | E13: 1.8 | F13: =IF(OR(E3="g",I2="无"),0,1) -> 0 | G13: =C13*D13/10000 -> 0.19008 | H13: =VLOOKUP($C$2,数据库!$B$1:$C$5,2,0) -> 195 | I13: =F13*G13*H13 -> 0
B14: A抽面 | C14: =G3-4 -> 96 | D14: 16 | E14: 1.8 | F14: =VLOOKUP($E$3,数据库!$A$28:$B$32,2,0) -> 0 | G14: =C14*D14/10000 -> 0.1536 | H14: =VLOOKUP($C$2,数据库!$B$1:$C$5,2,0) -> 195 | I14: =F14*G14*H14 -> 0
B15: A左抽帮 | C15: 49 | D15: 12 | E15: 1.8 | F15: =VLOOKUP($E$3,数据库!$A$28:$B$32,2,0) -> 0 | G15: =C15*D15/10000 -> 0.0588 | H15: =VLOOKUP($C$2,数据库!$B$1:$C$5,2,0) -> 195 | I15: =F15*G15*H15 -> 0
B16: A右抽帮 | C16: 49 | D16: 12 | E16: 1.8 | F16: =VLOOKUP($E$3,数据库!$A$28:$B$32,2,0) -> 0 | G16: =C16*D16/10000 -> 0.0588 | H16: =VLOOKUP($C$2,数据库!$B$1:$C$5,2,0) -> 195 | I16: =F16*G16*H16 -> 0
B17: A后抽堵 | C17: =G3-8.5 -> 91.5 | D17: 10.7 | E17: 1.8 | F17: =VLOOKUP($E$3,数据库!$A$28:$B$32,2,0) -> 0 | G17: =C17*D17/10000 -> 0.097905 | H17: =VLOOKUP($C$2,数据库!$B$1:$C$5,2,0) -> 195 | I17: =F17*G17*H17 -> 0
B18: A抽底 | C18: =G3-8.5 -> 91.5 | D18: 47.2 | E18: 1.8 | F18: =VLOOKUP($E$3,数据库!$A$28:$B$32,2,0) -> 0 | G18: =C18*D18/10000 -> 0.43188 | H18: =VLOOKUP($C$2,数据库!$B$1:$C$5,2,0) -> 195 | I18: =F18*G18*H18 -> 0
B19: B抽面 | C19: =G3-4 -> 96 | D19: 5 | E19: 1.8 | F19: =VLOOKUP($E$3,数据库!$A$35:$B$39,2,0) -> 0 | G19: =C19*D19/10000 -> 0.048 | H19: =VLOOKUP($C$2,数据库!$B$1:$C$5,2,0) -> 195 | I19: =F19*G19*H19 -> 0
B20: B左抽帮 | C20: 49 | D20: 5 | E20: 1.8 | F20: =VLOOKUP($E$3,数据库!$A$35:$B$39,2,0) -> 0 | G20: =C20*D20/10000 -> 0.0245 | H20: =VLOOKUP($C$2,数据库!$B$1:$C$5,2,0) -> 195 | I20: =F20*G20*H20 -> 0
B21: B右抽帮 | C21: 49 | D21: 5 | E21: 1.8 | F21: =VLOOKUP($E$3,数据库!$A$35:$B$39,2,0) -> 0 | G21: =C21*D21/10000 -> 0.0245 | H21: =VLOOKUP($C$2,数据库!$B$1:$C$5,2,0) -> 195 | I21: =F21*G21*H21 -> 0
B22: B后抽堵 | C22: =G3-8.5 -> 91.5 | D22: 4.2 | E22: 1.8 | F22: =VLOOKUP($E$3,数据库!$A$35:$B$39,2,0) -> 0 | G22: =C22*D22/10000 -> 0.03843 | H22: =VLOOKUP($C$2,数据库!$B$1:$C$5,2,0) -> 195 | I22: =F22*G22*H22 -> 0
B23: B抽底 | C23: =G3-8.5 -> 91.5 | D23: 47.2 | E23: 1.8 | F23: =VLOOKUP($E$3,数据库!$A$35:$B$39,2,0) -> 0 | G23: =C23*D23/10000 -> 0.43188 | H23: =VLOOKUP($C$2,数据库!$B$1:$C$5,2,0) -> 195 | I23: =F23*G23*H23 -> 0
B24: 踢脚线 | C24: =G3+45 -> 145 | D24: 5.5 | E24: 1.8 | F24: =IF(E3="g",0,1) -> 1 | G24: =C24*D24/10000 -> 0.07975 | H24: =VLOOKUP($C$2,数据库!$B$1:$C$5,2,0) -> 195 | I24: =F24*G24*H24 -> 15.55125
A25: 五金 & 配件 | B25: 柜体连接 | C25: SW4 6.3×50mm 白锌合金 沉头螺丝 | G25: =G3*I3/320 -> 71.875 | H25: 0.1 | I25: =H25*G25 -> 7.1875
C26: 8×40mm 定位木销 | G26: =G25 -> 71.875 | H26: 0.1 | I26: =H26*G26 -> 7.1875
B27: 调整脚 | C27: Häfele AXILO® 基座系统 53–70 mm | G27: =IF($E$3="g",0,4) -> 4 | H27: 4.27 | I27: =H27*G27 -> 17.08
C28: Häfele AXILO® 压入式底座 | G28: =IF($E$3="g",0,4) -> 4 | H28: 5.68 | I28: =H28*G28 -> 22.72
B29: 铰链 | C29: {=IF($G$2="中国品牌",INDEX(数据库!$F$2:$F$9,MATCH("中国品牌",数据库!$E$2:$E$9,0)+ROW(A1)-1),IF($G$2="海外品牌",INDEX(数据库!$F$2:$F$9,MATCH("海外品牌",数据库!$E$2:$E$9,0)+ROW(A1)-1),C29))} -> DTC东泰 C81全盖铰链（铰杯螺丝孔间距调整为48mm） | G29: 8 | H29: {=IF($G$2="中国品牌",INDEX(数据库!$G$2:$G$9,MATCH("中国品牌",数据库!$E$2:$E$9,0)+ROW(A1)-1),IF($G$2="海外品牌",INDEX(数据库!$G$2:$G$9,MATCH("海外品牌",数据库!$E$2:$E$9,0)+ROW(A1)-1),H29))} -> 4 | I29: =H29*G29 -> 32
C30: {=IF($G$2="中国品牌",INDEX(数据库!$F$2:$F$9,MATCH("中国品牌",数据库!$E$2:$E$9,0)+ROW(A2)-1),IF($G$2="海外品牌",INDEX(数据库!$F$2:$F$9,MATCH("海外品牌",数据库!$E$2:$E$9,0)+ROW(A2)-1),C30))} -> DTC东泰 C81一字底座 | G30: =G29 -> 8 | H30: {=IF($G$2="中国品牌",INDEX(数据库!$G$2:$G$9,MATCH("中国品牌",数据库!$E$2:$E$9,0)+ROW(A2)-1),IF($G$2="海外品牌",INDEX(数据库!$G$2:$G$9,MATCH("海外品牌",数据库!$E$2:$E$9,0)+ROW(A2)-1),H30))} -> 1.2 | I30: =H30*G30 -> 9.6
C31: {=IF($G$2="中国品牌",INDEX(数据库!$F$2:$F$9,MATCH("中国品牌",数据库!$E$2:$E$9,0)+ROW(A3)-1),IF($G$2="海外品牌",INDEX(数据库!$F$2:$F$9,MATCH("海外品牌",数据库!$E$2:$E$9,0)+ROW(A3)-1),C31))} -> DTC东泰 铰链装饰盖 | G31: =G29 -> 8 | H31: {=IF($G$2="中国品牌",INDEX(数据库!$G$2:$G$9,MATCH("中国品牌",数据库!$E$2:$E$9,0)+ROW(A3)-1),IF($G$2="海外品牌",INDEX(数据库!$G$2:$G$9,MATCH("海外品牌",数据库!$E$2:$E$9,0)+ROW(A3)-1),H31))} -> 0.5 | I31: =H31*G31 -> 4
C32: {=IF($G$2="中国品牌",INDEX(数据库!$F$2:$F$9,MATCH("中国品牌",数据库!$E$2:$E$9,0)+ROW(A4)-1),IF($G$2="海外品牌",INDEX(数据库!$F$2:$F$9,MATCH("海外品牌",数据库!$E$2:$E$9,0)+ROW(A4)-1),C32))} -> DTC东泰 铰杯装饰盖 | G32: =G29 -> 8 | H32: {=IF($G$2="中国品牌",INDEX(数据库!$G$2:$G$9,MATCH("中国品牌",数据库!$E$2:$E$9,0)+ROW(A4)-1),IF($G$2="海外品牌",INDEX(数据库!$G$2:$G$9,MATCH("海外品牌",数据库!$E$2:$E$9,0)+ROW(A4)-1),H32))} -> 0.5 | I32: =H32*G32 -> 4
C33: Ø5mm×12mm 尼龙螺丝预埋颗粒 | G33: =G29*2 -> 16 | H33: 0.141 | I33: =H33*G33 -> 2.256
C34: M4×16 深螺纹镀镍螺丝 | G34: =G29*2 -> 16 | H34: =9.6/300 -> 0.032 | I34: =H34*G34 -> 0.512
C35: Ø37mm×12.8mm深 37孔无介防潮盖 | G35: =G29 -> 8 | H35: 0.128 | I35: =H35*G35 -> 1.024
B36: 照明 | C36: {=IF($G$2="中国品牌",INDEX(数据库!$F$26:$F$33,ROW(A1)),IF($G$2="海外品牌",INDEX(数据库!$F$26:$F$33,ROW(A1)+4),C36))} -> Led 超薄1010带边灯槽 /米 | G36: =IF(OR(I2="无",E3="g"),0,2.2) -> 0 | H36: {=IF($G$2="中国品牌",INDEX(数据库!$G$26:$G$33,ROW(A1)),IF($G$2="海外品牌",INDEX(数据库!$G$26:$G$33,ROW(A1)+4),H36))} -> 4.4 | I36: =H36*G36 -> 0
C37: {=IF($G$2="中国品牌",INDEX(数据库!$F$26:$F$33,ROW(A2)),IF($G$2="海外品牌",INDEX(数据库!$F$26:$F$33,ROW(A2)+4),C37))} -> 12V 4000K LED灯带 60珠 8mm /米 | G37: =G36 -> 0 | H37: {=IF($G$2="中国品牌",INDEX(数据库!$G$26:$G$33,ROW(A2)),IF($G$2="海外品牌",INDEX(数据库!$G$26:$G$33,ROW(A2)+4),H37))} -> 15 | I37: =H37*G37 -> 0
C38: {=IF($G$2="中国品牌",INDEX(数据库!$F$26:$F$33,ROW(A3)),IF($G$2="海外品牌",INDEX(数据库!$F$26:$F$33,ROW(A3)+4),C38))} -> 12V 36瓦变压器 | G38: =IF(OR(I2="无",E3="g"),0,IF(OR(I2="中国品牌",I2="海外品牌"),1,0)) -> 0 | H38: {=IF($G$2="中国品牌",INDEX(数据库!$G$26:$G$33,ROW(A3)),IF($G$2="海外品牌",INDEX(数据库!$G$26:$G$33,ROW(A3)+4),H38))} -> 85 | I38: =H38*G38 -> 0
C39: {=IF($G$2="中国品牌",INDEX(数据库!$F$26:$F$33,ROW(A4)),IF($G$2="海外品牌",INDEX(数据库!$F$26:$F$33,ROW(A4)+4),C39))} -> 12V 双头门碰感应器 | G39: =G38 -> 0 | H39: {=IF($G$2="中国品牌",INDEX(数据库!$G$26:$G$33,ROW(A4)),IF($G$2="海外品牌",INDEX(数据库!$G$26:$G$33,ROW(A4)+4),H39))} -> 47 | I39: =H39*G39 -> 0
C40: 12mm×7mm 数据线/光纤PVC方形线槽 | G40: =IF(OR(I2="无",E3="g"),0,IF(G3<=60,1.1,1.65)) -> 0 | H40: =14/5 -> 2.8 | I40: =H40*G40 -> 0
...

Sheet 数据库
A1: 板材 | B1: E2 国产板 | C1: 80 | E1: 五金-铰链
B2: 国产 兔宝宝 | C2: 120 | E2: 中国品牌 | F2: DTC东泰 C81全盖铰链（铰杯螺丝孔间距调整为48mm） | G2: 4
B3: 国产 克诺斯帮 | C3: 115 | F3: DTC东泰 C81一字底座 | G3: 1.2
B4: 德国 克诺斯邦 | C4: 155 | F4: DTC东泰 铰链装饰盖 | G4: 0.5
B5: 奥地利 爱格 | C5: 195 | F5: DTC东泰 铰杯装饰盖 | G5: 0.5
E6: 海外品牌 | F6: B1um百隆175H3100 MB快装集成阻尼 110°全盖 | G6: 20
A7: 门板材质 | B7: 柜体相同 | C7: 0 | F7: B1um百隆175H3100 快装铰链一字底座 偏心螺丝 | G7: 5
B8: 钢琴烤漆 | C8: 200 | F8: Blum百隆70.1503. 铰链装饰盖全盖镀镍 | G8: 1
B9: 肤感烤漆 | C9: 250 | F9: Blum百隆 TO-AB 铰杯装饰盖（大开口） | G9: 1
B10: 铝框AG玻璃 | C10: 270
B11: 实木贴皮 | C11: 300 | E11: 五金-挂衣杆
B12: 橡胶实木 | C12: 480 | E12: 中国品牌 | F12: 加厚铝合金静音条挂衣杆 /cm | G12: 0.35
B13: 白蜡实木 | C13: 830 | F13: 挂衣杆双侧法兰 /对 | G13: 5
E14: 海外品牌 | F14: Häfele海福乐 801.73.503 衣杆带顶部静音条 高级灰 /㎝ | G14: =216/3/100 -> 0.72
A15: 门板工艺 | B15: 无 | C15: 0 | F15: Häfele海福乐 801.73.503 衣杆托 侧装/顶装 高级灰 /对 | G15: 50
B16: 骨骼线（浅造型） | C16: 75
B17: 欧式（深造型） | C17: 148 | E17: 五金-反弹器
B18: 格栅门 | C18: 300 | E18: 中国品牌 | F18: 悍高 重型反弹器 L=70mm | G18: 2.2
E19: 海外品牌 | F19: Häfele海福乐 反弹器带橡胶缓冲器 M-PUSH L=80mm | G19: 22
A20: 层板数量
A21: a | B21: 2 | E21: 五金-上翻门支臂
A22: b | B22: 2 | E22: 中国品牌 | F22: H-03A任意停支撑杆 | G22: 14.5
A23: c | B23: 2 | E23: 海外品牌 | F23: Häfele海福乐 重载型任意停上翻铰链 | G23: 97
A24: d | B24: 3
A25: g | B25: 0 | E25: 照明
E26: 中国品牌 | F26: Led 超薄1010带边灯槽 /米 | G26: 4.4
A27: A抽屉数量 | F27: 12V 4000K LED灯带 60珠 8mm /米 | G27: 15
A28: a | B28: 0 | F28: 12V 36瓦变压器 | G28: 85
A29: b | B29: 0 | F29: 12V 双头门碰感应器 | G29: 47
A30: c | B30: 2 | E30: 海外品牌 | F30: Häfele Loox5 内嵌式型材1101，聚碳酸酯 /米 | G30: =41.58/3 -> 13.86
A31: d | B31: 2 | F31: Häfele Loox LED 2042，24V灯带 120珠 4000K /米 | G31: =200/5 -> 40
A32: g | B32: 0 | F32: Häfele Loox5 24 V 恒压，配电源线40W+多开关分控盒V2 | G32: =120+80 -> 200
F33: Loox5模块化门感应模块+导线（开孔调整为12mm） | G33: =33.27+16.12 -> 49.39
A34: B抽屉数量
A35: a | B35: 0 | E35: 五金-三合一
A36: b | B36: 0 | E36: 中国品牌 | F36: 常规三合一 | G36: 0.2
A37: c | B37: 0 | E37: 海外品牌 | F37: Häfele 抽屉三合一连接件 | G37: 0.8
A38: d | B38: 1
A39: g | B39: 0
